[2024-05-09T11:15:44.677+0000] {local_task_job_runner.py:120} INFO - ::group::Pre task execution logs
[2024-05-09T11:15:44.705+0000] {taskinstance.py:2076} INFO - Dependencies all met for dep_context=non-requeueable deps ti=<TaskInstance: days_except_friday_dag.except_friday_crawler_task manual__2024-05-09T11:15:43.764219+00:00 [queued]>
[2024-05-09T11:15:44.711+0000] {taskinstance.py:2076} INFO - Dependencies all met for dep_context=requeueable deps ti=<TaskInstance: days_except_friday_dag.except_friday_crawler_task manual__2024-05-09T11:15:43.764219+00:00 [queued]>
[2024-05-09T11:15:44.712+0000] {taskinstance.py:2306} INFO - Starting attempt 1 of 1
[2024-05-09T11:15:44.723+0000] {taskinstance.py:2330} INFO - Executing <Task(PythonOperator): except_friday_crawler_task> on 2024-05-09 11:15:43.764219+00:00
[2024-05-09T11:15:44.727+0000] {logging_mixin.py:188} WARNING - /home/airflow/.local/lib/python3.12/site-packages/airflow/task/task_runner/standard_task_runner.py:61 DeprecationWarning: This process (pid=837) is multi-threaded, use of fork() may lead to deadlocks in the child.
[2024-05-09T11:15:44.727+0000] {standard_task_runner.py:90} INFO - Running: ['airflow', 'tasks', 'run', 'days_except_friday_dag', 'except_friday_crawler_task', 'manual__2024-05-09T11:15:43.764219+00:00', '--job-id', '117', '--raw', '--subdir', 'DAGS_FOLDER/single_dag.py', '--cfg-path', '/tmp/tmp1tlh2u09']
[2024-05-09T11:15:44.728+0000] {standard_task_runner.py:63} INFO - Started process 838 to run task
[2024-05-09T11:15:44.729+0000] {standard_task_runner.py:91} INFO - Job 117: Subtask except_friday_crawler_task
[2024-05-09T11:15:44.744+0000] {logging_mixin.py:188} WARNING - /home/airflow/.local/lib/python3.12/site-packages/airflow/settings.py:195 DeprecationWarning: The sql_alchemy_conn option in [core] has been moved to the sql_alchemy_conn option in [database] - the old setting has been used, but please update your config.
[2024-05-09T11:15:44.777+0000] {task_command.py:426} INFO - Running <TaskInstance: days_except_friday_dag.except_friday_crawler_task manual__2024-05-09T11:15:43.764219+00:00 [running]> on host 5d069ed3d57a
[2024-05-09T11:15:44.858+0000] {taskinstance.py:2648} INFO - Exporting env vars: AIRFLOW_CTX_DAG_OWNER='airflow' AIRFLOW_CTX_DAG_ID='days_except_friday_dag' AIRFLOW_CTX_TASK_ID='except_friday_crawler_task' AIRFLOW_CTX_EXECUTION_DATE='2024-05-09T11:15:43.764219+00:00' AIRFLOW_CTX_TRY_NUMBER='1' AIRFLOW_CTX_DAG_RUN_ID='manual__2024-05-09T11:15:43.764219+00:00'
[2024-05-09T11:15:44.859+0000] {taskinstance.py:430} INFO - ::endgroup::
[2024-05-09T11:15:44.869+0000] {single_dag.py:49} INFO - This is an informational message
[2024-05-09T11:15:45.629+0000] {taskinstance.py:441} INFO - ::group::Post task execution logs
[2024-05-09T11:15:45.630+0000] {taskinstance.py:2905} ERROR - Task failed with exception
Traceback (most recent call last):
  File "/home/airflow/.local/lib/python3.12/site-packages/airflow/models/taskinstance.py", line 465, in _execute_task
    result = _execute_callable(context=context, **execute_callable_kwargs)
             ^^^^^^^^^^^^^^^^^^^^^^^^^^^^^^^^^^^^^^^^^^^^^^^^^^^^^^^^^^^^^
  File "/home/airflow/.local/lib/python3.12/site-packages/airflow/models/taskinstance.py", line 432, in _execute_callable
    return execute_callable(context=context, **execute_callable_kwargs)
           ^^^^^^^^^^^^^^^^^^^^^^^^^^^^^^^^^^^^^^^^^^^^^^^^^^^^^^^^^^^^
  File "/home/airflow/.local/lib/python3.12/site-packages/airflow/models/baseoperator.py", line 400, in wrapper
    return func(self, *args, **kwargs)
           ^^^^^^^^^^^^^^^^^^^^^^^^^^^
  File "/home/airflow/.local/lib/python3.12/site-packages/airflow/operators/python.py", line 235, in execute
    return_value = self.execute_callable()
                   ^^^^^^^^^^^^^^^^^^^^^^^
  File "/home/airflow/.local/lib/python3.12/site-packages/airflow/operators/python.py", line 252, in execute_callable
    return self.python_callable(*self.op_args, **self.op_kwargs)
           ^^^^^^^^^^^^^^^^^^^^^^^^^^^^^^^^^^^^^^^^^^^^^^^^^^^^^
  File "/opt/airflow/dags/single_dag.py", line 66, in run_crawler
    json.dump(combined_results, outfile, indent=4)
  File "/usr/local/lib/python3.12/json/__init__.py", line 179, in dump
    for chunk in iterable:
  File "/usr/local/lib/python3.12/json/encoder.py", line 430, in _iterencode
    yield from _iterencode_list(o, _current_indent_level)
  File "/usr/local/lib/python3.12/json/encoder.py", line 326, in _iterencode_list
    yield from chunks
  File "/usr/local/lib/python3.12/json/encoder.py", line 406, in _iterencode_dict
    yield from chunks
  File "/usr/local/lib/python3.12/json/encoder.py", line 439, in _iterencode
    o = _default(o)
        ^^^^^^^^^^^
  File "/usr/local/lib/python3.12/json/encoder.py", line 180, in default
    raise TypeError(f'Object of type {o.__class__.__name__} '
TypeError: Object of type datetime is not JSON serializable
[2024-05-09T11:15:45.748+0000] {taskinstance.py:1206} INFO - Marking task as FAILED. dag_id=days_except_friday_dag, task_id=except_friday_crawler_task, run_id=manual__2024-05-09T11:15:43.764219+00:00, execution_date=20240509T111543, start_date=20240509T111544, end_date=20240509T111545
[2024-05-09T11:15:45.760+0000] {standard_task_runner.py:110} ERROR - Failed to execute job 117 for task except_friday_crawler_task (Object of type datetime is not JSON serializable; 838)
[2024-05-09T11:15:45.786+0000] {local_task_job_runner.py:240} INFO - Task exited with return code 1
[2024-05-09T11:15:45.809+0000] {taskinstance.py:3498} INFO - 0 downstream tasks scheduled from follow-on schedule check
[2024-05-09T11:15:45.815+0000] {local_task_job_runner.py:222} INFO - ::endgroup::
