[2024-05-09T17:14:12.358+0000] {local_task_job_runner.py:120} INFO - ::group::Pre task execution logs
[2024-05-09T17:14:12.408+0000] {taskinstance.py:2076} INFO - Dependencies all met for dep_context=non-requeueable deps ti=<TaskInstance: days_except_friday_dag.except_friday_run_database_task manual__2024-05-09T17:14:08.335179+00:00 [queued]>
[2024-05-09T17:14:12.418+0000] {taskinstance.py:2076} INFO - Dependencies all met for dep_context=requeueable deps ti=<TaskInstance: days_except_friday_dag.except_friday_run_database_task manual__2024-05-09T17:14:08.335179+00:00 [queued]>
[2024-05-09T17:14:12.420+0000] {taskinstance.py:2306} INFO - Starting attempt 1 of 1
[2024-05-09T17:14:12.439+0000] {taskinstance.py:2330} INFO - Executing <Task(PythonOperator): except_friday_run_database_task> on 2024-05-09 17:14:08.335179+00:00
[2024-05-09T17:14:12.453+0000] {logging_mixin.py:188} WARNING - /home/airflow/.local/lib/python3.12/site-packages/airflow/task/task_runner/standard_task_runner.py:61 DeprecationWarning: This process (pid=271) is multi-threaded, use of fork() may lead to deadlocks in the child.
[2024-05-09T17:14:12.455+0000] {standard_task_runner.py:63} INFO - Started process 280 to run task
[2024-05-09T17:14:12.454+0000] {standard_task_runner.py:90} INFO - Running: ['airflow', 'tasks', 'run', 'days_except_friday_dag', 'except_friday_run_database_task', 'manual__2024-05-09T17:14:08.335179+00:00', '--job-id', '195', '--raw', '--subdir', 'DAGS_FOLDER/single_dag.py', '--cfg-path', '/tmp/tmpwsyr93rp']
[2024-05-09T17:14:12.457+0000] {standard_task_runner.py:91} INFO - Job 195: Subtask except_friday_run_database_task
[2024-05-09T17:14:12.484+0000] {logging_mixin.py:188} WARNING - /home/airflow/.local/lib/python3.12/site-packages/airflow/settings.py:195 DeprecationWarning: The sql_alchemy_conn option in [core] has been moved to the sql_alchemy_conn option in [database] - the old setting has been used, but please update your config.
[2024-05-09T17:14:12.551+0000] {task_command.py:426} INFO - Running <TaskInstance: days_except_friday_dag.except_friday_run_database_task manual__2024-05-09T17:14:08.335179+00:00 [running]> on host 2ac721f319c6
[2024-05-09T17:14:12.667+0000] {taskinstance.py:2648} INFO - Exporting env vars: AIRFLOW_CTX_DAG_OWNER='airflow' AIRFLOW_CTX_DAG_ID='days_except_friday_dag' AIRFLOW_CTX_TASK_ID='except_friday_run_database_task' AIRFLOW_CTX_EXECUTION_DATE='2024-05-09T17:14:08.335179+00:00' AIRFLOW_CTX_TRY_NUMBER='1' AIRFLOW_CTX_DAG_RUN_ID='manual__2024-05-09T17:14:08.335179+00:00'
[2024-05-09T17:14:12.670+0000] {taskinstance.py:430} INFO - ::endgroup::
[2024-05-09T17:14:12.728+0000] {taskinstance.py:441} INFO - ::group::Post task execution logs
[2024-05-09T17:14:12.729+0000] {taskinstance.py:2905} ERROR - Task failed with exception
Traceback (most recent call last):
  File "/home/airflow/.local/lib/python3.12/site-packages/airflow/models/taskinstance.py", line 465, in _execute_task
    result = _execute_callable(context=context, **execute_callable_kwargs)
             ^^^^^^^^^^^^^^^^^^^^^^^^^^^^^^^^^^^^^^^^^^^^^^^^^^^^^^^^^^^^^
  File "/home/airflow/.local/lib/python3.12/site-packages/airflow/models/taskinstance.py", line 432, in _execute_callable
    return execute_callable(context=context, **execute_callable_kwargs)
           ^^^^^^^^^^^^^^^^^^^^^^^^^^^^^^^^^^^^^^^^^^^^^^^^^^^^^^^^^^^^
  File "/home/airflow/.local/lib/python3.12/site-packages/airflow/models/baseoperator.py", line 400, in wrapper
    return func(self, *args, **kwargs)
           ^^^^^^^^^^^^^^^^^^^^^^^^^^^
  File "/home/airflow/.local/lib/python3.12/site-packages/airflow/operators/python.py", line 235, in execute
    return_value = self.execute_callable()
                   ^^^^^^^^^^^^^^^^^^^^^^^
  File "/home/airflow/.local/lib/python3.12/site-packages/airflow/operators/python.py", line 252, in execute_callable
    return self.python_callable(*self.op_args, **self.op_kwargs)
           ^^^^^^^^^^^^^^^^^^^^^^^^^^^^^^^^^^^^^^^^^^^^^^^^^^^^^
  File "/opt/airflow/dags/single_dag.py", line 101, in insert_data_to_table
    cur.execute("""
psycopg2.errors.UniqueViolation: duplicate key value violates unique constraint "pg_class_relname_nsp_index"
DETAIL:  Key (relname, relnamespace)=(incidence_table_id_seq, 2200) already exists.

[2024-05-09T17:14:12.768+0000] {taskinstance.py:1206} INFO - Marking task as FAILED. dag_id=days_except_friday_dag, task_id=except_friday_run_database_task, run_id=manual__2024-05-09T17:14:08.335179+00:00, execution_date=20240509T171408, start_date=20240509T171412, end_date=20240509T171412
[2024-05-09T17:14:12.788+0000] {standard_task_runner.py:110} ERROR - Failed to execute job 195 for task except_friday_run_database_task (duplicate key value violates unique constraint "pg_class_relname_nsp_index"
DETAIL:  Key (relname, relnamespace)=(incidence_table_id_seq, 2200) already exists.
; 280)
[2024-05-09T17:14:12.836+0000] {local_task_job_runner.py:240} INFO - Task exited with return code 1
[2024-05-09T17:14:12.853+0000] {taskinstance.py:3498} INFO - 0 downstream tasks scheduled from follow-on schedule check
[2024-05-09T17:14:12.857+0000] {local_task_job_runner.py:222} INFO - ::endgroup::
